<?xml version="1.0"?> 
<robot name="t1">
	
	<material name="white">
	   <color rgba="1 1 1 1"/>
	</material>

	<link name="base_link">
		<visual>
			<geometry>
				<box size="2 1 1"/>
			</geometry>
		</visual>
		<material name="white"/>
		<collision>
			<geometry>
				<box size="2 1 1"/>
			</geometry>
		</collision>
		<inertial>
			<mass value="10"/>
    			<inertia ixx="4.16" ixy="0.0" ixz="0.0" iyy="1.66" iyz="0.0" izz="4.16"/>
		</inertial>
	</link>

	<link name="left_back_wheel">
		<visual>
			<geometry>
				<cylinder length="0.2" radius="0.6"/>
			</geometry>
			<origin rpy="1.5708 0 0" xyz="0 0 0"/>
		</visual>
		<collision>
			<geometry>
				<cylinder length="0.2" radius="0.6"/>
			</geometry>
			<origin rpy="1.5708 0 0" xyz="0 0 0"/>
		</collision>
		<inertial>
			<mass value="5"/>
    			<inertia ixx="1.09" ixy="0.0" ixz="0.0" iyy="1.09" iyz="0.0" izz="0.9"/>
		</inertial>
	</link>
	<joint name="left_back_wheel_joint" type="continuous">
		<parent link="base_link"/>
		<child link="left_back_wheel"/>
		<axis xyz="0 1 0"/>
		<origin xyz="-0.7 -0.6 -0.1"/>
	</joint>

	<link name="right_back_wheel">
		<visual>
			<geometry>
				<cylinder length="0.2" radius="0.6"/>
			</geometry>
			<origin rpy="1.5708 0 0" xyz="0 0 0"/>
		</visual>
		<collision>
			<geometry>
				<cylinder length="0.2" radius="0.6"/>
			</geometry>
			<origin rpy="1.5708 0 0" xyz="0 0 0"/>
		</collision>
		<inertial>
			<mass value="5"/>
    			<inertia ixx="1.09" ixy="0.0" ixz="0.0" iyy="1.09" iyz="0.0" izz="0.9"/>
		</inertial>
	</link>
	<joint name="right_back_wheel_joint" type="continuous">
		<parent link="base_link"/>
		<child link="right_back_wheel"/>
		<axis xyz="0 1 0"/>
		<origin xyz="-0.7 0.6 -0.1"/>
	</joint>

	<link name="front_left_wheel">
		<visual>
			<geometry>
				<cylinder length="0.2" radius="0.6"/>
			</geometry>
			<origin rpy="1.5708 0 0" xyz="0 0 0"/>
		</visual>
		<collision>
			<geometry>
				<cylinder length="0.2" radius="0.6"/>
			</geometry>
			<origin rpy="1.5708 0 0" xyz="0 0 0"/>
		</collision>
		<inertial>
			<mass value="5"/>
    			<inertia ixx="1.09" ixy="0.0" ixz="0.0" iyy="1.09" iyz="0.0" izz="0.9"/>
		</inertial>
	</link>
	<joint name="front_left_wheel_joint" type="continuous">
		<parent link="base_link"/>
		<child link="front_left_wheel"/>
		<axis xyz="0 1 0"/>
		<origin xyz="0.7 -0.6 -0.1"/>
	</joint>

	<link name="front_right_wheel">
		<visual>
			<geometry>
				<cylinder length="0.2" radius="0.6"/>
			</geometry>
			<origin rpy="1.5708 0 0" xyz="0 0 0"/>
		</visual>
		<collision>
			<geometry>
				<cylinder length="0.2" radius="0.6"/>
			</geometry>
			<origin rpy="1.5708 0 0" xyz="0 0 0"/>
		</collision>
		<inertial>
			<mass value="5"/>
    			<inertia ixx="1.09" ixy="0.0" ixz="0.0" iyy="1.09" iyz="0.0" izz="0.9"/>
		</inertial>
	</link>
	<joint name="front_right_wheel_joint" type="continuous">
		<parent link="base_link"/>
		<child link="front_right_wheel"/>
		<axis xyz="0 1 0"/>
		<origin xyz="0.7 0.6 -0.1"/>
	</joint>
</robot>
